<robot name="drone">
 <material name="grey">
  <color rgba="0.7 0.7 0.7 1" />
 </material>
 <material name="red">
  <color rgba="0.7 0 0 1" />
 </material>
 <material name="black">
  <color rgba="0.2 0.2 0.2 1" />
 </material>
 <link name="root_link">
  <inertial>
   <origin rpy="0 0 0" xyz="0 0 0" />
   <mass value="0" />
   <inertia ixx="0" ixy="0" ixz="0" iyy="0" iyz="0" izz="0" />
  </inertial>
 </link>
 <joint name="fixed_joint_base_fuselage" type="fixed">
  <parent link="root_link" />
  <child link="fuselage" />
  <origin rpy="3.141592653589793 0 0" xyz="0 0 0" />
 </joint>
 <link name="fuselage">
  <inertial>
   <origin rpy="0 0 0" xyz="-0.32 0 -0.02" />
   <mass value="0.875" />
   <inertia ixx="0.05" ixy="0" ixz="0" iyy="0.05" iyz="0" izz="0.096" />
  </inertial>
  <visual>
   <origin rpy="0 0 0" xyz="0 0 0" />
   <geometry>
    <mesh filename="package://ros_muav/meshes/fixed_wing_fuselage.stl" scale="0.001 0.001 0.001" />
   </geometry>
   <material name="grey" />
  </visual>
 </link>
 <joint name="fixed_joint_aero_frame_fuselage" type="fixed">
  <parent link="fuselage" />
  <child link="aero_frame_fuselage" />
  <origin rpy="0 3.141592653589793 0" xyz="-0.32 0 -0.02" />
 </joint>
 <link name="aero_frame_fuselage" />
 <joint name="fixed_joint_aileron_wing" type="fixed">
  <parent link="fuselage" />
  <child link="fuselage_aileron_0" />
  <origin rpy="0 0 0" xyz="-0.364 -0.275 -0.042" />
 </joint>
 <link name="fuselage_aileron_0">
  <inertial>
   <mass value="0.018" />
   <origin rpy="0 0 0" xyz="0 0 0" />
   <inertia ixx="2.13e-06" ixy="0" ixz="0" iyy="2.13e-06" iyz="0" izz="2.13e-06" />
  </inertial>
 </link>
 <joint name="joint_0__aileron_wing" type="revolute">
  <parent link="fuselage_aileron_0" />
  <child link="aileron_wing" />
  <origin rpy="0 0 0" xyz="0 0 0" />
  <axis xyz="0 1 0" />
  <limit effort="0.26" lower="-0.3490658503988659" upper="0.3490658503988659" velocity="5.4" />
  <dynamics damping="1" friction="0" />
 </joint>
 <link name="aileron_wing">
  <inertial>
   <origin rpy="0 0 0" xyz="-0.02 0 0" />
   <mass value="0.013" />
   <inertia ixx="9e-05" ixy="0" ixz="0" iyy="2e-06" iyz="0" izz="9e-05" />
  </inertial>
  <visual>
   <origin rpy="0 0 0" xyz="0 0 0" />
   <geometry>
    <mesh filename="package://ros_muav/meshes/fixed_wing_left_aileron.stl" scale="0.001 0.001 0.001" />
   </geometry>
   <material name="red" />
  </visual>
 </link>
 <joint name="fixed_joint_right_aileron_wing" type="fixed">
  <parent link="fuselage" />
  <child link="fuselage_right_aileron_0" />
  <origin rpy="0 0 0" xyz="-0.364 0.275 -0.042" />
 </joint>
 <link name="fuselage_right_aileron_0">
  <inertial>
   <mass value="0" />
   <origin rpy="0 0 0" xyz="0 0 0" />
   <inertia ixx="0" ixy="0" ixz="0" iyy="0" iyz="0" izz="0" />
  </inertial>
 </link>
 <joint name="joint_0_fixed_right_aileron_wing" type="fixed">
  <parent link="fuselage_right_aileron_0" />
  <child link="right_aileron_wing" />
  <origin rpy="0 0 0" xyz="0 0 0" />
  <axis xyz="0 0 0" />
 </joint>
 <link name="right_aileron_wing">
  <inertial>
   <origin rpy="0 0 0" xyz="-0.02 0 0" />
   <mass value="0.013" />
   <inertia ixx="9e-05" ixy="0" ixz="0" iyy="2e-06" iyz="0" izz="9e-05" />
  </inertial>
  <visual>
   <origin rpy="0 0 0" xyz="0 0 0" />
   <geometry>
    <mesh filename="package://ros_muav/meshes/fixed_wing_right_aileron.stl" scale="0.001 0.001 0.001" />
   </geometry>
   <material name="red" />
  </visual>
 </link>
 <joint name="fixed_joint_rudder_wing" type="fixed">
  <parent link="fuselage" />
  <child link="fuselage_rudder_0" />
  <origin rpy="0 0 0" xyz="-0.82 0 0.01" />
 </joint>
 <link name="fuselage_rudder_0">
  <inertial>
   <mass value="0.018" />
   <origin rpy="0 0 0" xyz="0 0 0" />
   <inertia ixx="2.13e-06" ixy="0" ixz="0" iyy="2.13e-06" iyz="0" izz="2.13e-06" />
  </inertial>
 </link>
 <joint name="joint_0__rudder_wing" type="revolute">
  <parent link="fuselage_rudder_0" />
  <child link="rudder_wing" />
  <origin rpy="0 0 0" xyz="0 0 0" />
  <axis xyz="0 0 1" />
  <limit effort="0.26" lower="-0.3490658503988659" upper="0.3490658503988659" velocity="5.4" />
  <dynamics damping="1" friction="0" />
 </joint>
 <link name="rudder_wing">
  <inertial>
   <origin rpy="0 0 0" xyz="-0.013 0 -0.075" />
   <mass value="0.003" />
   <inertia ixx="6e-06" ixy="0" ixz="0" iyy="6e-06" iyz="0" izz="2e-05" />
  </inertial>
  <visual>
   <origin rpy="0 0 0" xyz="0 0 0" />
   <geometry>
    <mesh filename="package://ros_muav/meshes/fixed_wing_rudder.stl" scale="0.001 0.001 0.001" />
   </geometry>
   <material name="red" />
  </visual>
 </link>
 <joint name="fixed_joint_elevator_wing" type="fixed">
  <parent link="fuselage" />
  <child link="fuselage_elevator_0" />
  <origin rpy="0 0 0" xyz="-0.82 0 0.015" />
 </joint>
 <link name="fuselage_elevator_0">
  <inertial>
   <mass value="0.018" />
   <origin rpy="0 0 0" xyz="0 0 0" />
   <inertia ixx="2.13e-06" ixy="0" ixz="0" iyy="2.13e-06" iyz="0" izz="2.13e-06" />
  </inertial>
 </link>
 <joint name="joint_0__elevator_wing" type="revolute">
  <parent link="fuselage_elevator_0" />
  <child link="elevator_wing" />
  <origin rpy="0 0 0" xyz="0 0 0" />
  <axis xyz="0 1 0" />
  <limit effort="0.26" lower="-0.3490658503988659" upper="0.3490658503988659" velocity="5.4" />
  <dynamics damping="1" friction="0" />
 </joint>
 <link name="elevator_wing">
  <inertial>
   <origin rpy="0 0 0" xyz="-0.02 0 0" />
   <mass value="0.014" />
   <inertia ixx="0.0002" ixy="0" ixz="0" iyy="2e-06" iyz="0" izz="0.0002" />
  </inertial>
  <visual>
   <origin rpy="0 0 0" xyz="0 0 0" />
   <geometry>
    <mesh filename="package://ros_muav/meshes/fixed_wing_elevator.stl" scale="0.001 0.001 0.001" />
   </geometry>
   <material name="red" />
  </visual>
 </link>
 <joint name="fixed_joint_prop_frame_fuselage" type="fixed">
  <parent link="fuselage" />
  <child link="prop_frame_fuselage" />
  <origin rpy="3.141592653589793 -1.5707963267948966 0" xyz="0 0 0" />
 </joint>
 <link name="prop_frame_fuselage">
  <inertial>
   <mass value="0.04" />
   <origin rpy="0 0 0" xyz="0 0 0" />
   <inertia ixx="3.7625e-05" ixy="0" ixz="0" iyy="3.7625e-05" iyz="0" izz="7.5e-05" />
  </inertial>
  <visual>
   <origin rpy="0 0 0" xyz="0 0 0" />
   <geometry>
    <mesh filename="package://ros_muav/meshes/propeller.stl" scale="0.001 0.001 0.001" />
   </geometry>
   <material name="black" />
  </visual>
 </link>
 <joint name="fixed_joint_collision_0" type="fixed">
  <parent link="fuselage" />
  <child link="collision_frame_0" />
  <origin rpy="0 0 0" xyz="0 0 0" />
 </joint>
 <link name="collision_frame_0" />
 <joint name="fixed_joint_collision_1" type="fixed">
  <parent link="fuselage" />
  <child link="collision_frame_1" />
  <origin rpy="0 0 0" xyz="-0.850 0 0" />
 </joint>
 <link name="collision_frame_1" />
 <joint name="fixed_joint_collision_2" type="fixed">
  <parent link="fuselage" />
  <child link="collision_frame_2" />
  <origin rpy="0 0 0" xyz="-0.410 0.700 -0.100" />
 </joint>
 <link name="collision_frame_2" />
 <joint name="fixed_joint_collision_3" type="fixed">
  <parent link="fuselage" />
  <child link="collision_frame_3" />
  <origin rpy="0 0 0" xyz="-0.410 -0.700 -0.100" />
 </joint>
 <link name="collision_frame_3" />
</robot>